Workbook

Sheet Competencias_2S_2026
B2: Competencias que se formaran en el Segundo Semestre 2026
B4: No | C4: Tipo | D4: Verbo en Presente | E4: Objeto de la acción | F4: [Palabras conectoreas] Herramientas o metodología | G4: [Palabras conectoreas] Condiciones específicas | H4: Nivel
B5: 1 | P5: =IF(TRIM(C6)="", "", C6)
C6: =D5 & " " & E5 & " " & F5 & " " & G5
B7: 2 | P7: =IF(TRIM(C8)="", "", C8)
C8: =D7 & " " & E7 & " " & F7 & " " & G7
B9: 3 | P9: =IF(TRIM(C10)="", "", C10)
C10: =D9 & " " & E9 & " " & F9 & " " & G9
B11: 4 | P11: =IF(TRIM(C12)="", "", C12)
C12: =D11 & " " & E11 & " " & F11 & " " & G11
B13: 5 | P13: =IF(TRIM(C14)="", "", C14)
C14: =D13 & " " & E13 & " " & F13 & " " & G13
B15: 6 | P15: =IF(TRIM(C16)="", "", C16)
C16: =D15 & " " & E15 & " " & F15 & " " & G15
B17: 7 | P17: =IF(TRIM(C18)="", "", C18)
C18: =D17 & " " & E17 & " " & F17 & " " & G17
B19: 8 | P19: =IF(TRIM(C20)="", "", C20)
C20: =D19 & " " & E19 & " " & F19 & " " & G19

Sheet Contenido Curricular
B1: Contenido Curricular Introducción a la Programación y Computación 1 2S 2026
B3: Unidad | C3: Tema | D3: Subtema | E3: Mes | F3: Semana | G3: Competencia
B4: 1. Introducción a la Programación | C4: Introducción a los fundamentos de Programación | D4: Algoritmos
B5: 1. Introducción a la Programación | C5: Introducción a los fundamentos de Programación | D5: Diagramas de Flujo
B6: 1. Introducción a la Programación | C6: Introducción a los fundamentos de Programación | D6: Pseudocódigo
B7: 2. Introducción al versionamiento | C7: Introducción al manejo de control de versiones | D7: Introducción a versionamiento
B8: 2. Introducción al versionamiento | C8: Introducción al manejo de control de versiones | D8: Herramientas de control de versiones
B9: 2. Introducción al versionamiento | C9: Introducción al manejo de control de versiones | D9: Tareas básicas de Git
B10: 2. Introducción al versionamiento | C10: Introducción al manejo de control de versiones | D10: Colaboración en repositorios remotos
B11: 3. Introducción a Java | C11: Introducción a Java - Parte 1 | D11: ¿Qué es Java?
B12: 3. Introducción a Java | C12: Introducción a Java - Parte 2 | D12: Versiones y ambientes de java (JDK, JRE, JVM)
B13: 3. Introducción a Java | C13: Introducción a Java - Parte 2 | D13: Operadores aritméticos, relacionales y lógicos
B14: 3. Introducción a Java | C14: Introducción a Java - Parte 3 | D14: Características de Java
B15: 3. Introducción a Java | C15: Introducción a Java - Parte 3 | D15: Input y output
... B72: 12. Cloud computing | C72: Cloud Computing | D72: Proveedores de Nube

Sheet Semana Diagnostico
B2: Diseño de Contenido Curricular
A4: Curso | B4: 770 - Introducción a la Programación y Computación 1
A5: Semana | B5: 1
A6: Tiempo | B6: 0
A8: 1. Bienvenida y Presentación | E8: Tiempo Aproximado | F8: 0
E9: No puedes excederte mas de 15 minutos
A10: Nombre y Formacion Academica | F10: ⬅️ | G10: Estos puntos son recomendaciones de los puntos a tratar durante tu presentacion, si no usaras estos eres libre de agregar mas filas para indicar que haras. En los recuadros de la derecha colocar breve resumen de lo que planeas decir. No debes ser muy especifico seran pequeñas anotaciones que te ayudaran a recordar lo que planeaste
A11: Experiencia docente y profesional
A12: Expectativas sobre la dinámica del curso
A13: Tiempo que emplearas
A15: 2. Evaluación de Conocimientos Previos | E15: Tiempo Aproximado | F15: 0
E16: No puedes excederte mas de 45 minutos
A17: Redactaras de 15 a 20 preguntas con sus respectivas respuestas, por lo que debes escoger los temas que evaluaras | F17: ⬅️ | G17: En los recuadros de la derecha deberas colocar las preguntas que planeas realizar con sus respectivas respuestas. En el segundo recuadro deberas colocar un breve resumen de lo que tienes planificado para la parte practica del curso previo al que estas impartiendo.
A18: Redactaras una parte practica
A19: Tiempo que emplearas
A21: 3. Presentación de los Estudiantes | E21: Tiempo Aproximado | F21: 0
E22: No puedes excederte mas de 30 minutos
A23: Selección al Azar de 5 Estudiantes | F23: ⬅️ | G23: En el primer recuadro colocaras la metodollogia que adoptaras para la eleccion de los estudiantes. En el segundo recuadro colocaras la redaccion de las preguntas que comprendan los siguientes puntos respecto al estudiante: Nombre. Intereses y expectativas sobre el curso. Experiencia previa relacionada con el curso (si aplica). Un dato curioso sobre sí mismo. Consideras que la prueba de conocimientos previos esta acorde al conocimiento que se te brindo en su momento. Que tan comodo se sintio con la prueba anterior.
A24: Preguntas que responderan los estudiantes afortunados
A25: Tiempo que emplearas
A27: 4. Censo de Horarios de Calificación | E27: Tiempo Aproximado | F27: 0
E28: No puedes excederte mas de 5 minutos Esta actividad quedara abierta hasta el fin de la clase. pero emplearas 5 min especificos para la actividad
A29: Link de google forms donde este el cuestionario | F29: ⬅️ | G29: Esta actividad te ayudara a realizar un censo de posibles horarios de calificacion y que tus estudiantes esten enterados y puedan preveer los dias de calificacion y asi mismo el horario. Deberas colocar en los recuadros de la derecha link de Google form libre para correos institucionales, esto para garantizar una sola respuesta por estudiante. Tambien deberas colocar los posibles horarios y dias que tentativamente tendrias disponibles para colocarlos en el google form.
A30: Dias y posibles Horarios de calificacion
A31: Tiempo que emplearas
A33: 5. Mostrar Programa del Curso | E33: Tiempo Aproximado | F33: 0
E34: No puedes excederte mas de 30 minutos
A35: Tiempo que emplearas
A37: 6. Evaluación de Conocimientos del Curso Actual | E37: Tiempo Aproximado | F37: 0
E38: No puedes excederte mas de 15 minutos
A39: Redactaras 20 preguntas con sus respectivas respuestas
A40: Tiempo que emplearas

Sheet S. 2
B2: Diseño de la Sesión de Laboratorio
B4: Curso | C4: 770 - Introducción a la Programación y Computación 1
B5: Semana | C5: 2
B6: Tiempo | C6: =H10+H21+H45+H70
B7: Ponderación | C7: =B50+B61
B8: Validación de Tiempo | C8: =IF(H51<=0, "❌ ERROR: La Actividad 1 debe tener un tiempo mayor a 0.", IF(H21>60, "❌ ERROR: El 'Área de Conocimiento' no puede exceder los 60 min.", IF((H10+H21+H45)<100, "❌ ERROR: El tiempo total debe ser de al menos 100 min.", "✅ VALIDACIÓN CORRECTA")))
A10: 1. Área Actitudinal (Saber Ser) | G10: Tiempo | H10: 5
G11: Tiene que estar en un rango de 3 a 5 minutos
A12: Nombre del Valor
A13: Tiempo Aproximado
A14: Descripcion
A17: Como se relaciona con los conocimientos de la sesion y se aplicaria
A21: 2. Área Conocimiento (Saber) | G21: Tiempo | H21: 60
G22: No puede exceder los 60 minutos
A23: Competencia a desarrollar
A24: Competencia a desarrollar
A26: 2.1 Contenido
A27: No. | B27: Unidad | D27: Tema | F27: Sub Tema
A28: 1 | B28: =IFERROR(INDEX(_xlfn.FILTER('Contenido Curricular'!$B$4:$B$100, 'Contenido Curricular'!$F$4:$F$100=2), 1), "") | D28: =IFERROR(INDEX(_xlfn.FILTER('Contenido Curricular'!$C$4:$C$100, 'Contenido Curricular'!$F$4:$F$100=2), 1), "") | F28: =IFERROR(INDEX(_xlfn.FILTER('Contenido Curricular'!$D$4:$D$100, 'Contenido Curricular'!$F$4:$F$100=2), 1), "")
A29: 2 | B29: =IFERROR(INDEX(_xlfn.FILTER('Contenido Curricular'!$B$4:$B$100, 'Contenido Curricular'!$F$4:$F$100=2), 2), "") | D29: =IFERROR(INDEX(_xlfn.FILTER('Contenido Curricular'!$C$4:$C$100, 'Contenido Curricular'!$F$4:$F$100=2), 2), "") | F29: =IFERROR(INDEX(_xlfn.FILTER('Contenido Curricular'!$D$4:$D$100, 'Contenido Curricular'!$F$4:$F$100=2), 2), "")
A30: 3 | B30: =IFERROR(INDEX(_xlfn.FILTER('Contenido Curricular'!$B$4:$B$100, 'Contenido Curricular'!$F$4:$F$100=2), 3), "") | D30: =IFERROR(INDEX(_xlfn.FILTER('Contenido Curricular'!$C$4:$C$100, 'Contenido Curricular'!$F$4:$F$100=2), 3), "") | F30: =IFERROR(INDEX(_xlfn.FILTER('Contenido Curricular'!$D$4:$D$100, 'Contenido Curricular'!$F$4:$F$100=2), 3), "")
A31: 4 | B31: =IFERROR(INDEX(_xlfn.FILTER('Contenido Curricular'!$B$4:$B$100, 'Contenido Curricular'!$F$4:$F$100=2), 4), "") | D31: =IFERROR(INDEX(_xlfn.FILTER('Contenido Curricular'!$C$4:$C$100, 'Contenido Curricular'!$F$4:$F$100=2), 4), "") | F31: =IFERROR(INDEX(_xlfn.FILTER('Contenido Curricular'!$D$4:$D$100, 'Contenido Curricular'!$F$4:$F$100=2), 4), "")
A32: 5 | B32: =IFERROR(INDEX(_xlfn.FILTER('Contenido Curricular'!$B$4:$B$100, 'Contenido Curricular'!$F$4:$F$100=2), 5), "") | D32: =IFERROR(INDEX(_xlfn.FILTER('Contenido Curricular'!$C$4:$C$100, 'Contenido Curricular'!$F$4:$F$100=2), 5), "") | F32: =IFERROR(INDEX(_xlfn.FILTER('Contenido Curricular'!$D$4:$D$100, 'Contenido Curricular'!$F$4:$F$100=2), 5), "")
A33: 6 | B33: =IFERROR(INDEX(_xlfn.FILTER('Contenido Curricular'!$B$4:$B$100, 'Contenido Curricular'!$F$4:$F$100=2), 6), "") | D33: =IFERROR(INDEX(_xlfn.FILTER('Contenido Curricular'!$C$4:$C$100, 'Contenido Curricular'!$F$4:$F$100=2), 6), "") | F33: =IFERROR(INDEX(_xlfn.FILTER('Contenido Curricular'!$D$4:$D$100, 'Contenido Curricular'!$F$4:$F$100=2), 6), "")
A34: 7 | B34: =IFERROR(INDEX(_xlfn.FILTER('Contenido Curricular'!$B$4:$B$100, 'Contenido Curricular'!$F$4:$F$100=2), 7), "") | D34: =IFERROR(INDEX(_xlfn.FILTER('Contenido Curricular'!$C$4:$C$100, 'Contenido Curricular'!$F$4:$F$100=2), 7), "") | F34: =IFERROR(INDEX(_xlfn.FILTER('Contenido Curricular'!$D$4:$D$100, 'Contenido Curricular'!$F$4:$F$100=2), 7), "")
A35: 8 | B35: =IFERROR(INDEX(_xlfn.FILTER('Contenido Curricular'!$B$4:$B$100, 'Contenido Curricular'!$F$4:$F$100=2), 8), "") | D35: =IFERROR(INDEX(_xlfn.FILTER('Contenido Curricular'!$C$4:$C$100, 'Contenido Curricular'!$F$4:$F$100=2), 8), "") | F35: =IFERROR(INDEX(_xlfn.FILTER('Contenido Curricular'!$D$4:$D$100, 'Contenido Curricular'!$F$4:$F$100=2), 8), "")
A36: 9 | B36: =IFERROR(INDEX(_xlfn.FILTER('Contenido Curricular'!$B$4:$B$100, 'Contenido Curricular'!$F$4:$F$100=2), 9), "") | D36: =IFERROR(INDEX(_xlfn.FILTER('Contenido Curricular'!$C$4:$C$100, 'Contenido Curricular'!$F$4:$F$100=2), 9), "") | F36: =IFERROR(INDEX(_xlfn.FILTER('Contenido Curricular'!$D$4:$D$100, 'Contenido Curricular'!$F$4:$F$100=2), 9), "")
A37: 10 | B37: =IFERROR(INDEX(_xlfn.FILTER('Contenido Curricular'!$B$4:$B$100, 'Contenido Curricular'!$F$4:$F$100=2), 10), "") | D37: =IFERROR(INDEX(_xlfn.FILTER('Contenido Curricular'!$C$4:$C$100, 'Contenido Curricular'!$F$4:$F$100=2), 10), "") | F37: =IFERROR(INDEX(_xlfn.FILTER('Contenido Curricular'!$D$4:$D$100, 'Contenido Curricular'!$F$4:$F$100=2), 10), "")
A38: 2.2 Recursos Educativos
A39: Tipo de Recurso a utilizar | C39: Tipo | E39: Rango Aproximando | G39: Tiempo Aproximado
A40: Presentacion | C40: Obligatorio | E40: 15-25 minutos | G40: 25
A41: Video | C41: Obligatorio | E41: 3 a 6 minutos | G41: 10
A42: Lectura | C42: Optativo | E42: 3-5 minutos | G42: 5
A43: Ejercicio Demostrativo | C43: Obligatorio | E43: 20-25 minutos | G43: 25
A45: 3. Área de Habilidades (Saber Hacer) | G45: Tiempo | H45: 35
G46: Tiene que estar en un rango de 30 a 50 minutos
A47: Actividad 1 (Obligatoria)
A48: Competencia que predomina en la actividad
A49: Tipo de Actividad | B49: Ejercicio practico
A50: Ponderación | B50: 0
...

Sheet S. 3
B2: Diseño de la Sesión de Laboratorio
B4: Curso | C4: 770 - Introducción a la Programación y Computación 1
B5: Semana | C5: 3
B6: Tiempo | C6: =H10+H21+H45+H70
B7: Ponderación | C7: =B50+B61
B8: Validación de Tiempo | C8: =IF(H51<=0, "❌ ERROR: La Actividad 1 debe tener un tiempo mayor a 0.", IF(H21>60, "❌ ERROR: El 'Área de Conocimiento' no puede exceder los 60 min.", IF((H10+H21+H45)<100, "❌ ERROR: El tiempo total debe ser de al menos 100 min.", "✅ VALIDACIÓN CORRECTA")))
A10: 1. Área Actitudinal (Saber Ser) | G10: Tiempo | H10: 5
G11: Tiene que estar en un rango de 3 a 5 minutos
A12: Nombre del Valor
A13: Tiempo Aproximado
A14: Descripcion
A17: Como se relaciona con los conocimientos de la sesion y se aplicaria
A21: 2. Área Conocimiento (Saber) | G21: Tiempo | H21: 60
G22: No puede exceder los 60 minutos
A23: Competencia a desarrollar
A24: Competencia a desarrollar
A26: 2.1 Contenido
A27: No. | B27: Unidad | D27: Tema | F27: Sub Tema
A28: 1 | B28: =IFERROR(INDEX(_xlfn.FILTER('Contenido Curricular'!$B$4:$B$100, 'Contenido Curricular'!$F$4:$F$100=3), 1), "") | D28: =IFERROR(INDEX(_xlfn.FILTER('Contenido Curricular'!$C$4:$C$100, 'Contenido Curricular'!$F$4:$F$100=3), 1), "") | F28: =IFERROR(INDEX(_xlfn.FILTER('Contenido Curricular'!$D$4:$D$100, 'Contenido Curricular'!$F$4:$F$100=3), 1), "")
A29: 2 | B29: =IFERROR(INDEX(_xlfn.FILTER('Contenido Curricular'!$B$4:$B$100, 'Contenido Curricular'!$F$4:$F$100=3), 2), "") | D29: =IFERROR(INDEX(_xlfn.FILTER('Contenido Curricular'!$C$4:$C$100, 'Contenido Curricular'!$F$4:$F$100=3), 2), "") | F29: =IFERROR(INDEX(_xlfn.FILTER('Contenido Curricular'!$D$4:$D$100, 'Contenido Curricular'!$F$4:$F$100=3), 2), "")
A30: 3 | B30: =IFERROR(INDEX(_xlfn.FILTER('Contenido Curricular'!$B$4:$B$100, 'Contenido Curricular'!$F$4:$F$100=3), 3), "") | D30: =IFERROR(INDEX(_xlfn.FILTER('Contenido Curricular'!$C$4:$C$100, 'Contenido Curricular'!$F$4:$F$100=3), 3), "") | F30: =IFERROR(INDEX(_xlfn.FILTER('Contenido Curricular'!$D$4:$D$100, 'Contenido Curricular'!$F$4:$F$100=3), 3), "")
A31: 4 | B31: =IFERROR(INDEX(_xlfn.FILTER('Contenido Curricular'!$B$4:$B$100, 'Contenido Curricular'!$F$4:$F$100=3), 4), "") | D31: =IFERROR(INDEX(_xlfn.FILTER('Contenido Curricular'!$C$4:$C$100, 'Contenido Curricular'!$F$4:$F$100=3), 4), "") | F31: =IFERROR(INDEX(_xlfn.FILTER('Contenido Curricular'!$D$4:$D$100, 'Contenido Curricular'!$F$4:$F$100=3), 4), "")
A32: 5 | B32: =IFERROR(INDEX(_xlfn.FILTER('Contenido Curricular'!$B$4:$B$100, 'Contenido Curricular'!$F$4:$F$100=3), 5), "") | D32: =IFERROR(INDEX(_xlfn.FILTER('Contenido Curricular'!$C$4:$C$100, 'Contenido Curricular'!$F$4:$F$100=3), 5), "") | F32: =IFERROR(INDEX(_xlfn.FILTER('Contenido Curricular'!$D$4:$D$100, 'Contenido Curricular'!$F$4:$F$100=3), 5), "")
A33: 6 | B33: =IFERROR(INDEX(_xlfn.FILTER('Contenido Curricular'!$B$4:$B$100, 'Contenido Curricular'!$F$4:$F$100=3), 6), "") | D33: =IFERROR(INDEX(_xlfn.FILTER('Contenido Curricular'!$C$4:$C$100, 'Contenido Curricular'!$F$4:$F$100=3), 6), "") | F33: =IFERROR(INDEX(_xlfn.FILTER('Contenido Curricular'!$D$4:$D$100, 'Contenido Curricular'!$F$4:$F$100=3), 6), "")
A34: 7 | B34: =IFERROR(INDEX(_xlfn.FILTER('Contenido Curricular'!$B$4:$B$100, 'Contenido Curricular'!$F$4:$F$100=3), 7), "") | D34: =IFERROR(INDEX(_xlfn.FILTER('Contenido Curricular'!$C$4:$C$100, 'Contenido Curricular'!$F$4:$F$100=3), 7), "") | F34: =IFERROR(INDEX(_xlfn.FILTER('Contenido Curricular'!$D$4:$D$100, 'Contenido Curricular'!$F$4:$F$100=3), 7), "")
A35: 8 | B35: =IFERROR(INDEX(_xlfn.FILTER('Contenido Curricular'!$B$4:$B$100, 'Contenido Curricular'!$F$4:$F$100=3), 8), "") | D35: =IFERROR(INDEX(_xlfn.FILTER('Contenido Curricular'!$C$4:$C$100, 'Contenido Curricular'!$F$4:$F$100=3), 8), "") | F35: =IFERROR(INDEX(_xlfn.FILTER('Contenido Curricular'!$D$4:$D$100, 'Contenido Curricular'!$F$4:$F$100=3), 8), "")
A36: 9 | B36: =IFERROR(INDEX(_xlfn.FILTER('Contenido Curricular'!$B$4:$B$100, 'Contenido Curricular'!$F$4:$F$100=3), 9), "") | D36: =IFERROR(INDEX(_xlfn.FILTER('Contenido Curricular'!$C$4:$C$100, 'Contenido Curricular'!$F$4:$F$100=3), 9), "") | F36: =IFERROR(INDEX(_xlfn.FILTER('Contenido Curricular'!$D$4:$D$100, 'Contenido Curricular'!$F$4:$F$100=3), 9), "")
A37: 10 | B37: =IFERROR(INDEX(_xlfn.FILTER('Contenido Curricular'!$B$4:$B$100, 'Contenido Curricular'!$F$4:$F$100=3), 10), "") | D37: =IFERROR(INDEX(_xlfn.FILTER('Contenido Curricular'!$C$4:$C$100, 'Contenido Curricular'!$F$4:$F$100=3), 10), "") | F37: =IFERROR(INDEX(_xlfn.FILTER('Contenido Curricular'!$D$4:$D$100, 'Contenido Curricular'!$F$4:$F$100=3), 10), "")
A38: 2.2 Recursos Educativos
A39: Tipo de Recurso a utilizar | C39: Tipo | E39: Rango Aproximando | G39: Tiempo Aproximado
A40: Presentacion | C40: Obligatorio | E40: 15-25 minutos | G40: 25
A41: Video | C41: Obligatorio | E41: 3 a 6 minutos | G41: 10
A42: Lectura | C42: Optativo | E42: 3-5 minutos | G42: 5
A43: Ejercicio Demostrativo | C43: Obligatorio | E43: 20-25 minutos | G43: 25
A45: 3. Área de Habilidades (Saber Hacer) | G45: Tiempo | H45: 35
G46: Tiene que estar en un rango de 30 a 50 minutos
A47: Actividad 1 (Obligatoria)
A48: Competencia que predomina en la actividad
A49: Tipo de Actividad | B49: Ejercicio practico
A50: Ponderación | B50: 0
...

Sheet S. 4
B2: Diseño de la Sesión de Laboratorio
B4: Curso | C4: 770 - Introducción a la Programación y Computación 1
B5: Semana | C5: 4
B6: Tiempo | C6: =H10+H21+H45+H70
B7: Ponderación | C7: =B50+B61
B8: Validación de Tiempo | C8: =IF(H51<=0, "❌ ERROR: La Actividad 1 debe tener un tiempo mayor a 0.", IF(H21>60, "❌ ERROR: El 'Área de Conocimiento' no puede exceder los 60 min.", IF((H10+H21+H45)<100, "❌ ERROR: El tiempo total debe ser de al menos 100 min.", "✅ VALIDACIÓN CORRECTA")))
A10: 1. Área Actitudinal (Saber Ser) | G10: Tiempo | H10: 5
G11: Tiene que estar en un rango de 3 a 5 minutos
A12: Nombre del Valor
A13: Tiempo Aproximado
A14: Descripcion
A17: Como se relaciona con los conocimientos de la sesion y se aplicaria
A21: 2. Área Conocimiento (Saber) | G21: Tiempo | H21: 60
G22: No puede exceder los 60 minutos
A23: Competencia a desarrollar
A24: Competencia a desarrollar
A26: 2.1 Contenido
A27: No. | B27: Unidad | D27: Tema | F27: Sub Tema
A28: 1 | B28: =IFERROR(INDEX(_xlfn.FILTER('Contenido Curricular'!$B$4:$B$100, 'Contenido Curricular'!$F$4:$F$100=4), 1), "") | D28: =IFERROR(INDEX(_xlfn.FILTER('Contenido Curricular'!$C$4:$C$100, 'Contenido Curricular'!$F$4:$F$100=4), 1), "") | F28: =IFERROR(INDEX(_xlfn.FILTER('Contenido Curricular'!$D$4:$D$100, 'Contenido Curricular'!$F$4:$F$100=4), 1), "")
A29: 2 | B29: =IFERROR(INDEX(_xlfn.FILTER('Contenido Curricular'!$B$4:$B$100, 'Contenido Curricular'!$F$4:$F$100=4), 2), "") | D29: =IFERROR(INDEX(_xlfn.FILTER('Contenido Curricular'!$C$4:$C$100, 'Contenido Curricular'!$F$4:$F$100=4), 2), "") | F29: =IFERROR(INDEX(_xlfn.FILTER('Contenido Curricular'!$D$4:$D$100, 'Contenido Curricular'!$F$4:$F$100=4), 2), "")
A30: 3 | B30: =IFERROR(INDEX(_xlfn.FILTER('Contenido Curricular'!$B$4:$B$100, 'Contenido Curricular'!$F$4:$F$100=4), 3), "") | D30: =IFERROR(INDEX(_xlfn.FILTER('Contenido Curricular'!$C$4:$C$100, 'Contenido Curricular'!$F$4:$F$100=4), 3), "") | F30: =IFERROR(INDEX(_xlfn.FILTER('Contenido Curricular'!$D$4:$D$100, 'Contenido Curricular'!$F$4:$F$100=4), 3), "")
A31: 4 | B31: =IFERROR(INDEX(_xlfn.FILTER('Contenido Curricular'!$B$4:$B$100, 'Contenido Curricular'!$F$4:$F$100=4), 4), "") | D31: =IFERROR(INDEX(_xlfn.FILTER('Contenido Curricular'!$C$4:$C$100, 'Contenido Curricular'!$F$4:$F$100=4), 4), "") | F31: =IFERROR(INDEX(_xlfn.FILTER('Contenido Curricular'!$D$4:$D$100, 'Contenido Curricular'!$F$4:$F$100=4), 4), "")
A32: 5 | B32: =IFERROR(INDEX(_xlfn.FILTER('Contenido Curricular'!$B$4:$B$100, 'Contenido Curricular'!$F$4:$F$100=4), 5), "") | D32: =IFERROR(INDEX(_xlfn.FILTER('Contenido Curricular'!$C$4:$C$100, 'Contenido Curricular'!$F$4:$F$100=4), 5), "") | F32: =IFERROR(INDEX(_xlfn.FILTER('Contenido Curricular'!$D$4:$D$100, 'Contenido Curricular'!$F$4:$F$100=4), 5), "")
A33: 6 | B33: =IFERROR(INDEX(_xlfn.FILTER('Contenido Curricular'!$B$4:$B$100, 'Contenido Curricular'!$F$4:$F$100=4), 6), "") | D33: =IFERROR(INDEX(_xlfn.FILTER('Contenido Curricular'!$C$4:$C$100, 'Contenido Curricular'!$F$4:$F$100=4), 6), "") | F33: =IFERROR(INDEX(_xlfn.FILTER('Contenido Curricular'!$D$4:$D$100, 'Contenido Curricular'!$F$4:$F$100=4), 6), "")
A34: 7 | B34: =IFERROR(INDEX(_xlfn.FILTER('Contenido Curricular'!$B$4:$B$100, 'Contenido Curricular'!$F$4:$F$100=4), 7), "") | D34: =IFERROR(INDEX(_xlfn.FILTER('Contenido Curricular'!$C$4:$C$100, 'Contenido Curricular'!$F$4:$F$100=4), 7), "") | F34: =IFERROR(INDEX(_xlfn.FILTER('Contenido Curricular'!$D$4:$D$100, 'Contenido Curricular'!$F$4:$F$100=4), 7), "")
A35: 8 | B35: =IFERROR(INDEX(_xlfn.FILTER('Contenido Curricular'!$B$4:$B$100, 'Contenido Curricular'!$F$4:$F$100=4), 8), "") | D35: =IFERROR(INDEX(_xlfn.FILTER('Contenido Curricular'!$C$4:$C$100, 'Contenido Curricular'!$F$4:$F$100=4), 8), "") | F35: =IFERROR(INDEX(_xlfn.FILTER('Contenido Curricular'!$D$4:$D$100, 'Contenido Curricular'!$F$4:$F$100=4), 8), "")
A36: 9 | B36: =IFERROR(INDEX(_xlfn.FILTER('Contenido Curricular'!$B$4:$B$100, 'Contenido Curricular'!$F$4:$F$100=4), 9), "") | D36: =IFERROR(INDEX(_xlfn.FILTER('Contenido Curricular'!$C$4:$C$100, 'Contenido Curricular'!$F$4:$F$100=4), 9), "") | F36: =IFERROR(INDEX(_xlfn.FILTER('Contenido Curricular'!$D$4:$D$100, 'Contenido Curricular'!$F$4:$F$100=4), 9), "")
A37: 10 | B37: =IFERROR(INDEX(_xlfn.FILTER('Contenido Curricular'!$B$4:$B$100, 'Contenido Curricular'!$F$4:$F$100=4), 10), "") | D37: =IFERROR(INDEX(_xlfn.FILTER('Contenido Curricular'!$C$4:$C$100, 'Contenido Curricular'!$F$4:$F$100=4), 10), "") | F37: =IFERROR(INDEX(_xlfn.FILTER('Contenido Curricular'!$D$4:$D$100, 'Contenido Curricular'!$F$4:$F$100=4), 10), "")
A38: 2.2 Recursos Educativos
A39: Tipo de Recurso a utilizar | C39: Tipo | E39: Rango Aproximando | G39: Tiempo Aproximado
A40: Presentacion | C40: Obligatorio | E40: 15-25 minutos | G40: 25
A41: Video | C41: Obligatorio | E41: 3 a 6 minutos | G41: 10
A42: Lectura | C42: Optativo | E42: 3-5 minutos | G42: 5
A43: Ejercicio Demostrativo | C43: Obligatorio | E43: 20-25 minutos | G43: 25
A45: 3. Área de Habilidades (Saber Hacer) | G45: Tiempo | H45: 35
G46: Tiene que estar en un rango de 30 a 50 minutos
A47: Actividad 1 (Obligatoria)
A48: Competencia que predomina en la actividad
A49: Tipo de Actividad | B49: Ejercicio practico
A50: Ponderación | B50: 0
...

Sheet S. 5
B2: Diseño de la Sesión de Laboratorio
B4: Curso | C4: 770 - Introducción a la Programación y Computación 1
B5: Semana | C5: 5
B6: Tiempo | C6: =H10+H21+H45+H70
B7: Ponderación | C7: =B50+B61
B8: Validación de Tiempo | C8: =IF(H51<=0, "❌ ERROR: La Actividad 1 debe tener un tiempo mayor a 0.", IF(H21>60, "❌ ERROR: El 'Área de Conocimiento' no puede exceder los 60 min.", IF((H10+H21+H45)<100, "❌ ERROR: El tiempo total debe ser de al menos 100 min.", "✅ VALIDACIÓN CORRECTA")))
A10: 1. Área Actitudinal (Saber Ser) | G10: Tiempo | H10: 5
G11: Tiene que estar en un rango de 3 a 5 minutos
A12: Nombre del Valor
A13: Tiempo Aproximado
A14: Descripcion
A17: Como se relaciona con los conocimientos de la sesion y se aplicaria
A21: 2. Área Conocimiento (Saber) | G21: Tiempo | H21: 60
G22: No puede exceder los 60 minutos
A23: Competencia a desarrollar
A24: Competencia a desarrollar
A26: 2.1 Contenido
A27: No. | B27: Unidad | D27: Tema | F27: Sub Tema
A28: 1 | B28: =IFERROR(INDEX(_xlfn.FILTER('Contenido Curricular'!$B$4:$B$100, 'Contenido Curricular'!$F$4:$F$100=5), 1), "") | D28: =IFERROR(INDEX(_xlfn.FILTER('Contenido Curricular'!$C$4:$C$100, 'Contenido Curricular'!$F$4:$F$100=5), 1), "") | F28: =IFERROR(INDEX(_xlfn.FILTER('Contenido Curricular'!$D$4:$D$100, 'Contenido Curricular'!$F$4:$F$100=5), 1), "")
A29: 2 | B29: =IFERROR(INDEX(_xlfn.FILTER('Contenido Curricular'!$B$4:$B$100, 'Contenido Curricular'!$F$4:$F$100=5), 2), "") | D29: =IFERROR(INDEX(_xlfn.FILTER('Contenido Curricular'!$C$4:$C$100, 'Contenido Curricular'!$F$4:$F$100=5), 2), "") | F29: =IFERROR(INDEX(_xlfn.FILTER('Contenido Curricular'!$D$4:$D$100, 'Contenido Curricular'!$F$4:$F$100=5), 2), "")
A30: 3 | B30: =IFERROR(INDEX(_xlfn.FILTER('Contenido Curricular'!$B$4:$B$100, 'Contenido Curricular'!$F$4:$F$100=5), 3), "") | D30: =IFERROR(INDEX(_xlfn.FILTER('Contenido Curricular'!$C$4:$C$100, 'Contenido Curricular'!$F$4:$F$100=5), 3), "") | F30: =IFERROR(INDEX(_xlfn.FILTER('Contenido Curricular'!$D$4:$D$100, 'Contenido Curricular'!$F$4:$F$100=5), 3), "")
A31: 4 | B31: =IFERROR(INDEX(_xlfn.FILTER('Contenido Curricular'!$B$4:$B$100, 'Contenido Curricular'!$F$4:$F$100=5), 4), "") | D31: =IFERROR(INDEX(_xlfn.FILTER('Contenido Curricular'!$C$4:$C$100, 'Contenido Curricular'!$F$4:$F$100=5), 4), "") | F31: =IFERROR(INDEX(_xlfn.FILTER('Contenido Curricular'!$D$4:$D$100, 'Contenido Curricular'!$F$4:$F$100=5), 4), "")
A32: 5 | B32: =IFERROR(INDEX(_xlfn.FILTER('Contenido Curricular'!$B$4:$B$100, 'Contenido Curricular'!$F$4:$F$100=5), 5), "") | D32: =IFERROR(INDEX(_xlfn.FILTER('Contenido Curricular'!$C$4:$C$100, 'Contenido Curricular'!$F$4:$F$100=5), 5), "") | F32: =IFERROR(INDEX(_xlfn.FILTER('Contenido Curricular'!$D$4:$D$100, 'Contenido Curricular'!$F$4:$F$100=5), 5), "")
A33: 6 | B33: =IFERROR(INDEX(_xlfn.FILTER('Contenido Curricular'!$B$4:$B$100, 'Contenido Curricular'!$F$4:$F$100=5), 6), "") | D33: =IFERROR(INDEX(_xlfn.FILTER('Contenido Curricular'!$C$4:$C$100, 'Contenido Curricular'!$F$4:$F$100=5), 6), "") | F33: =IFERROR(INDEX(_xlfn.FILTER('Contenido Curricular'!$D$4:$D$100, 'Contenido Curricular'!$F$4:$F$100=5), 6), "")
A34: 7 | B34: =IFERROR(INDEX(_xlfn.FILTER('Contenido Curricular'!$B$4:$B$100, 'Contenido Curricular'!$F$4:$F$100=5), 7), "") | D34: =IFERROR(INDEX(_xlfn.FILTER('Contenido Curricular'!$C$4:$C$100, 'Contenido Curricular'!$F$4:$F$100=5), 7), "") | F34: =IFERROR(INDEX(_xlfn.FILTER('Contenido Curricular'!$D$4:$D$100, 'Contenido Curricular'!$F$4:$F$100=5), 7), "")
A35: 8 | B35: =IFERROR(INDEX(_xlfn.FILTER('Contenido Curricular'!$B$4:$B$100, 'Contenido Curricular'!$F$4:$F$100=5), 8), "") | D35: =IFERROR(INDEX(_xlfn.FILTER('Contenido Curricular'!$C$4:$C$100, 'Contenido Curricular'!$F$4:$F$100=5), 8), "") | F35: =IFERROR(INDEX(_xlfn.FILTER('Contenido Curricular'!$D$4:$D$100, 'Contenido Curricular'!$F$4:$F$100=5), 8), "")
A36: 9 | B36: =IFERROR(INDEX(_xlfn.FILTER('Contenido Curricular'!$B$4:$B$100, 'Contenido Curricular'!$F$4:$F$100=5), 9), "") | D36: =IFERROR(INDEX(_xlfn.FILTER('Contenido Curricular'!$C$4:$C$100, 'Contenido Curricular'!$F$4:$F$100=5), 9), "") | F36: =IFERROR(INDEX(_xlfn.FILTER('Contenido Curricular'!$D$4:$D$100, 'Contenido Curricular'!$F$4:$F$100=5), 9), "")
A37: 10 | B37: =IFERROR(INDEX(_xlfn.FILTER('Contenido Curricular'!$B$4:$B$100, 'Contenido Curricular'!$F$4:$F$100=5), 10), "") | D37: =IFERROR(INDEX(_xlfn.FILTER('Contenido Curricular'!$C$4:$C$100, 'Contenido Curricular'!$F$4:$F$100=5), 10), "") | F37: =IFERROR(INDEX(_xlfn.FILTER('Contenido Curricular'!$D$4:$D$100, 'Contenido Curricular'!$F$4:$F$100=5), 10), "")
A38: 2.2 Recursos Educativos
A39: Tipo de Recurso a utilizar | C39: Tipo | E39: Rango Aproximando | G39: Tiempo Aproximado
A40: Presentacion | C40: Obligatorio | E40: 15-25 minutos | G40: 25
A41: Video | C41: Obligatorio | E41: 3 a 6 minutos | G41: 10
A42: Lectura | C42: Optativo | E42: 3-5 minutos | G42: 5
A43: Ejercicio Demostrativo | C43: Obligatorio | E43: 20-25 minutos | G43: 25
A45: 3. Área de Habilidades (Saber Hacer) | G45: Tiempo | H45: 35
G46: Tiene que estar en un rango de 30 a 50 minutos
A47: Actividad 1 (Obligatoria)
A48: Competencia que predomina en la actividad
A49: Tipo de Actividad | B49: Ejercicio practico
A50: Ponderación | B50: 0
...

Sheet S. 6
B2: Diseño de la Sesión de Laboratorio
B4: Curso | C4: 770 - Introducción a la Programación y Computación 1
B5: Semana | C5: 6
B6: Tiempo | C6: =H10+H21+H45+H70
B7: Ponderación | C7: =B50+B61
B8: Validación de Tiempo | C8: =IF(H51<=0, "❌ ERROR: La Actividad 1 debe tener un tiempo mayor a 0.", IF(H21>60, "❌ ERROR: El 'Área de Conocimiento' no puede exceder los 60 min.", IF((H10+H21+H45)<100, "❌ ERROR: El tiempo total debe ser de al menos 100 min.", "✅ VALIDACIÓN CORRECTA")))
A10: 1. Área Actitudinal (Saber Ser) | G10: Tiempo | H10: 5
G11: Tiene que estar en un rango de 3 a 5 minutos
A12: Nombre del Valor
A13: Tiempo Aproximado
A14: Descripcion
A17: Como se relaciona con los conocimientos de la sesion y se aplicaria
A21: 2. Área Conocimiento (Saber) | G21: Tiempo | H21: 60
G22: No puede exceder los 60 minutos
A23: Competencia a desarrollar
A24: Competencia a desarrollar
A26: 2.1 Contenido
A27: No. | B27: Unidad | D27: Tema | F27: Sub Tema
A28: 1 | B28: =IFERROR(INDEX(_xlfn.FILTER('Contenido Curricular'!$B$4:$B$100, 'Contenido Curricular'!$F$4:$F$100=6), 1), "") | D28: =IFERROR(INDEX(_xlfn.FILTER('Contenido Curricular'!$C$4:$C$100, 'Contenido Curricular'!$F$4:$F$100=6), 1), "") | F28: =IFERROR(INDEX(_xlfn.FILTER('Contenido Curricular'!$D$4:$D$100, 'Contenido Curricular'!$F$4:$F$100=6), 1), "")
A29: 2 | B29: =IFERROR(INDEX(_xlfn.FILTER('Contenido Curricular'!$B$4:$B$100, 'Contenido Curricular'!$F$4:$F$100=6), 2), "") | D29: =IFERROR(INDEX(_xlfn.FILTER('Contenido Curricular'!$C$4:$C$100, 'Contenido Curricular'!$F$4:$F$100=6), 2), "") | F29: =IFERROR(INDEX(_xlfn.FILTER('Contenido Curricular'!$D$4:$D$100, 'Contenido Curricular'!$F$4:$F$100=6), 2), "")
A30: 3 | B30: =IFERROR(INDEX(_xlfn.FILTER('Contenido Curricular'!$B$4:$B$100, 'Contenido Curricular'!$F$4:$F$100=6), 3), "") | D30: =IFERROR(INDEX(_xlfn.FILTER('Contenido Curricular'!$C$4:$C$100, 'Contenido Curricular'!$F$4:$F$100=6), 3), "") | F30: =IFERROR(INDEX(_xlfn.FILTER('Contenido Curricular'!$D$4:$D$100, 'Contenido Curricular'!$F$4:$F$100=6), 3), "")
A31: 4 | B31: =IFERROR(INDEX(_xlfn.FILTER('Contenido Curricular'!$B$4:$B$100, 'Contenido Curricular'!$F$4:$F$100=6), 4), "") | D31: =IFERROR(INDEX(_xlfn.FILTER('Contenido Curricular'!$C$4:$C$100, 'Contenido Curricular'!$F$4:$F$100=6), 4), "") | F31: =IFERROR(INDEX(_xlfn.FILTER('Contenido Curricular'!$D$4:$D$100, 'Contenido Curricular'!$F$4:$F$100=6), 4), "")
A32: 5 | B32: =IFERROR(INDEX(_xlfn.FILTER('Contenido Curricular'!$B$4:$B$100, 'Contenido Curricular'!$F$4:$F$100=6), 5), "") | D32: =IFERROR(INDEX(_xlfn.FILTER('Contenido Curricular'!$C$4:$C$100, 'Contenido Curricular'!$F$4:$F$100=6), 5), "") | F32: =IFERROR(INDEX(_xlfn.FILTER('Contenido Curricular'!$D$4:$D$100, 'Contenido Curricular'!$F$4:$F$100=6), 5), "")
A33: 6 | B33: =IFERROR(INDEX(_xlfn.FILTER('Contenido Curricular'!$B$4:$B$100, 'Contenido Curricular'!$F$4:$F$100=6), 6), "") | D33: =IFERROR(INDEX(_xlfn.FILTER('Contenido Curricular'!$C$4:$C$100, 'Contenido Curricular'!$F$4:$F$100=6), 6), "") | F33: =IFERROR(INDEX(_xlfn.FILTER('Contenido Curricular'!$D$4:$D$100, 'Contenido Curricular'!$F$4:$F$100=6), 6), "")
A34: 7 | B34: =IFERROR(INDEX(_xlfn.FILTER('Contenido Curricular'!$B$4:$B$100, 'Contenido Curricular'!$F$4:$F$100=6), 7), "") | D34: =IFERROR(INDEX(_xlfn.FILTER('Contenido Curricular'!$C$4:$C$100, 'Contenido Curricular'!$F$4:$F$100=6), 7), "") | F34: =IFERROR(INDEX(_xlfn.FILTER('Contenido Curricular'!$D$4:$D$100, 'Contenido Curricular'!$F$4:$F$100=6), 7), "")
A35: 8 | B35: =IFERROR(INDEX(_xlfn.FILTER('Contenido Curricular'!$B$4:$B$100, 'Contenido Curricular'!$F$4:$F$100=6), 8), "") | D35: =IFERROR(INDEX(_xlfn.FILTER('Contenido Curricular'!$C$4:$C$100, 'Contenido Curricular'!$F$4:$F$100=6), 8), "") | F35: =IFERROR(INDEX(_xlfn.FILTER('Contenido Curricular'!$D$4:$D$100, 'Contenido Curricular'!$F$4:$F$100=6), 8), "")
A36: 9 | B36: =IFERROR(INDEX(_xlfn.FILTER('Contenido Curricular'!$B$4:$B$100, 'Contenido Curricular'!$F$4:$F$100=6), 9), "") | D36: =IFERROR(INDEX(_xlfn.FILTER('Contenido Curricular'!$C$4:$C$100, 'Contenido Curricular'!$F$4:$F$100=6), 9), "") | F36: =IFERROR(INDEX(_xlfn.FILTER('Contenido Curricular'!$D$4:$D$100, 'Contenido Curricular'!$F$4:$F$100=6), 9), "")
A37: 10 | B37: =IFERROR(INDEX(_xlfn.FILTER('Contenido Curricular'!$B$4:$B$100, 'Contenido Curricular'!$F$4:$F$100=6), 10), "") | D37: =IFERROR(INDEX(_xlfn.FILTER('Contenido Curricular'!$C$4:$C$100, 'Contenido Curricular'!$F$4:$F$100=6), 10), "") | F37: =IFERROR(INDEX(_xlfn.FILTER('Contenido Curricular'!$D$4:$D$100, 'Contenido Curricular'!$F$4:$F$100=6), 10), "")
A38: 2.2 Recursos Educativos
A39: Tipo de Recurso a utilizar | C39: Tipo | E39: Rango Aproximando | G39: Tiempo Aproximado
A40: Presentacion | C40: Obligatorio | E40: 15-25 minutos | G40: 25
A41: Video | C41: Obligatorio | E41: 3 a 6 minutos | G41: 10
A42: Lectura | C42: Optativo | E42: 3-5 minutos | G42: 5
A43: Ejercicio Demostrativo | C43: Obligatorio | E43: 20-25 minutos | G43: 25
A45: 3. Área de Habilidades (Saber Hacer) | G45: Tiempo | H45: 35
G46: Tiene que estar en un rango de 30 a 50 minutos
A47: Actividad 1 (Obligatoria)
A48: Competencia que predomina en la actividad
A49: Tipo de Actividad | B49: Ejercicio practico
A50: Ponderación | B50: 0
...

Sheet S. 7
B2: Diseño de la Sesión de Laboratorio
B4: Curso | C4: 770 - Introducción a la Programación y Computación 1
B5: Semana | C5: 7
B6: Tiempo | C6: =H10+H21+H45+H70
B7: Ponderación | C7: =B50+B61
B8: Validación de Tiempo | C8: =IF(H51<=0, "❌ ERROR: La Actividad 1 debe tener un tiempo mayor a 0.", IF(H21>60, "❌ ERROR: El 'Área de Conocimiento' no puede exceder los 60 min.", IF((H10+H21+H45)<100, "❌ ERROR: El tiempo total debe ser de al menos 100 min.", "✅ VALIDACIÓN CORRECTA")))
A10: 1. Área Actitudinal (Saber Ser) | G10: Tiempo | H10: 5
G11: Tiene que estar en un rango de 3 a 5 minutos
A12: Nombre del Valor
A13: Tiempo Aproximado
A14: Descripcion
A17: Como se relaciona con los conocimientos de la sesion y se aplicaria
A21: 2. Área Conocimiento (Saber) | G21: Tiempo | H21: 60
G22: No puede exceder los 60 minutos
A23: Competencia a desarrollar
A24: Competencia a desarrollar
A26: 2.1 Contenido
A27: No. | B27: Unidad | D27: Tema | F27: Sub Tema
A28: 1 | B28: =IFERROR(INDEX(_xlfn.FILTER('Contenido Curricular'!$B$4:$B$100, 'Contenido Curricular'!$F$4:$F$100=7), 1), "") | D28: =IFERROR(INDEX(_xlfn.FILTER('Contenido Curricular'!$C$4:$C$100, 'Contenido Curricular'!$F$4:$F$100=7), 1), "") | F28: =IFERROR(INDEX(_xlfn.FILTER('Contenido Curricular'!$D$4:$D$100, 'Contenido Curricular'!$F$4:$F$100=7), 1), "")
A29: 2 | B29: =IFERROR(INDEX(_xlfn.FILTER('Contenido Curricular'!$B$4:$B$100, 'Contenido Curricular'!$F$4:$F$100=7), 2), "") | D29: =IFERROR(INDEX(_xlfn.FILTER('Contenido Curricular'!$C$4:$C$100, 'Contenido Curricular'!$F$4:$F$100=7), 2), "") | F29: =IFERROR(INDEX(_xlfn.FILTER('Contenido Curricular'!$D$4:$D$100, 'Contenido Curricular'!$F$4:$F$100=7), 2), "")
A30: 3 | B30: =IFERROR(INDEX(_xlfn.FILTER('Contenido Curricular'!$B$4:$B$100, 'Contenido Curricular'!$F$4:$F$100=7), 3), "") | D30: =IFERROR(INDEX(_xlfn.FILTER('Contenido Curricular'!$C$4:$C$100, 'Contenido Curricular'!$F$4:$F$100=7), 3), "") | F30: =IFERROR(INDEX(_xlfn.FILTER('Contenido Curricular'!$D$4:$D$100, 'Contenido Curricular'!$F$4:$F$100=7), 3), "")
A31: 4 | B31: =IFERROR(INDEX(_xlfn.FILTER('Contenido Curricular'!$B$4:$B$100, 'Contenido Curricular'!$F$4:$F$100=7), 4), "") | D31: =IFERROR(INDEX(_xlfn.FILTER('Contenido Curricular'!$C$4:$C$100, 'Contenido Curricular'!$F$4:$F$100=7), 4), "") | F31: =IFERROR(INDEX(_xlfn.FILTER('Contenido Curricular'!$D$4:$D$100, 'Contenido Curricular'!$F$4:$F$100=7), 4), "")
A32: 5 | B32: =IFERROR(INDEX(_xlfn.FILTER('Contenido Curricular'!$B$4:$B$100, 'Contenido Curricular'!$F$4:$F$100=7), 5), "") | D32: =IFERROR(INDEX(_xlfn.FILTER('Contenido Curricular'!$C$4:$C$100, 'Contenido Curricular'!$F$4:$F$100=7), 5), "") | F32: =IFERROR(INDEX(_xlfn.FILTER('Contenido Curricular'!$D$4:$D$100, 'Contenido Curricular'!$F$4:$F$100=7), 5), "")
A33: 6 | B33: =IFERROR(INDEX(_xlfn.FILTER('Contenido Curricular'!$B$4:$B$100, 'Contenido Curricular'!$F$4:$F$100=7), 6), "") | D33: =IFERROR(INDEX(_xlfn.FILTER('Contenido Curricular'!$C$4:$C$100, 'Contenido Curricular'!$F$4:$F$100=7), 6), "") | F33: =IFERROR(INDEX(_xlfn.FILTER('Contenido Curricular'!$D$4:$D$100, 'Contenido Curricular'!$F$4:$F$100=7), 6), "")
A34: 7 | B34: =IFERROR(INDEX(_xlfn.FILTER('Contenido Curricular'!$B$4:$B$100, 'Contenido Curricular'!$F$4:$F$100=7), 7), "") | D34: =IFERROR(INDEX(_xlfn.FILTER('Contenido Curricular'!$C$4:$C$100, 'Contenido Curricular'!$F$4:$F$100=7), 7), "") | F34: =IFERROR(INDEX(_xlfn.FILTER('Contenido Curricular'!$D$4:$D$100, 'Contenido Curricular'!$F$4:$F$100=7), 7), "")
A35: 8 | B35: =IFERROR(INDEX(_xlfn.FILTER('Contenido Curricular'!$B$4:$B$100, 'Contenido Curricular'!$F$4:$F$100=7), 8), "") | D35: =IFERROR(INDEX(_xlfn.FILTER('Contenido Curricular'!$C$4:$C$100, 'Contenido Curricular'!$F$4:$F$100=7), 8), "") | F35: =IFERROR(INDEX(_xlfn.FILTER('Contenido Curricular'!$D$4:$D$100, 'Contenido Curricular'!$F$4:$F$100=7), 8), "")
A36: 9 | B36: =IFERROR(INDEX(_xlfn.FILTER('Contenido Curricular'!$B$4:$B$100, 'Contenido Curricular'!$F$4:$F$100=7), 9), "") | D36: =IFERROR(INDEX(_xlfn.FILTER('Contenido Curricular'!$C$4:$C$100, 'Contenido Curricular'!$F$4:$F$100=7), 9), "") | F36: =IFERROR(INDEX(_xlfn.FILTER('Contenido Curricular'!$D$4:$D$100, 'Contenido Curricular'!$F$4:$F$100=7), 9), "")
A37: 10 | B37: =IFERROR(INDEX(_xlfn.FILTER('Contenido Curricular'!$B$4:$B$100, 'Contenido Curricular'!$F$4:$F$100=7), 10), "") | D37: =IFERROR(INDEX(_xlfn.FILTER('Contenido Curricular'!$C$4:$C$100, 'Contenido Curricular'!$F$4:$F$100=7), 10), "") | F37: =IFERROR(INDEX(_xlfn.FILTER('Contenido Curricular'!$D$4:$D$100, 'Contenido Curricular'!$F$4:$F$100=7), 10), "")
A38: 2.2 Recursos Educativos
A39: Tipo de Recurso a utilizar | C39: Tipo | E39: Rango Aproximando | G39: Tiempo Aproximado
A40: Presentacion | C40: Obligatorio | E40: 15-25 minutos | G40: 25
A41: Video | C41: Obligatorio | E41: 3 a 6 minutos | G41: 10
A42: Lectura | C42: Optativo | E42: 3-5 minutos | G42: 5
A43: Ejercicio Demostrativo | C43: Obligatorio | E43: 20-25 minutos | G43: 25
A45: 3. Área de Habilidades (Saber Hacer) | G45: Tiempo | H45: 35
G46: Tiene que estar en un rango de 30 a 50 minutos
A47: Actividad 1 (Obligatoria)
A48: Competencia que predomina en la actividad
A49: Tipo de Actividad | B49: Ejercicio practico
A50: Ponderación | B50: 0
...

Sheet S. 8
B2: Diseño de la Sesión de Laboratorio
B4: Curso | C4: 770 - Introducción a la Programación y Computación 1
B5: Semana | C5: 8
B6: Tiempo | C6: =H10+H21+H45+H70
B7: Ponderación | C7: =B50+B61
B8: Validación de Tiempo | C8: =IF(H51<=0, "❌ ERROR: La Actividad 1 debe tener un tiempo mayor a 0.", IF(H21>60, "❌ ERROR: El 'Área de Conocimiento' no puede exceder los 60 min.", IF((H10+H21+H45)<100, "❌ ERROR: El tiempo total debe ser de al menos 100 min.", "✅ VALIDACIÓN CORRECTA")))
A10: 1. Área Actitudinal (Saber Ser) | G10: Tiempo | H10: 5
G11: Tiene que estar en un rango de 3 a 5 minutos
A12: Nombre del Valor
A13: Tiempo Aproximado
A14: Descripcion
A17: Como se relaciona con los conocimientos de la sesion y se aplicaria
A21: 2. Área Conocimiento (Saber) | G21: Tiempo | H21: 60
G22: No puede exceder los 60 minutos
A23: Competencia a desarrollar
A24: Competencia a desarrollar
A26: 2.1 Contenido
A27: No. | B27: Unidad | D27: Tema | F27: Sub Tema
A28: 1 | B28: =IFERROR(INDEX(_xlfn.FILTER('Contenido Curricular'!$B$4:$B$100, 'Contenido Curricular'!$F$4:$F$100=8), 1), "") | D28: =IFERROR(INDEX(_xlfn.FILTER('Contenido Curricular'!$C$4:$C$100, 'Contenido Curricular'!$F$4:$F$100=8), 1), "") | F28: =IFERROR(INDEX(_xlfn.FILTER('Contenido Curricular'!$D$4:$D$100, 'Contenido Curricular'!$F$4:$F$100=8), 1), "")
A29: 2 | B29: =IFERROR(INDEX(_xlfn.FILTER('Contenido Curricular'!$B$4:$B$100, 'Contenido Curricular'!$F$4:$F$100=8), 2), "") | D29: =IFERROR(INDEX(_xlfn.FILTER('Contenido Curricular'!$C$4:$C$100, 'Contenido Curricular'!$F$4:$F$100=8), 2), "") | F29: =IFERROR(INDEX(_xlfn.FILTER('Contenido Curricular'!$D$4:$D$100, 'Contenido Curricular'!$F$4:$F$100=8), 2), "")
A30: 3 | B30: =IFERROR(INDEX(_xlfn.FILTER('Contenido Curricular'!$B$4:$B$100, 'Contenido Curricular'!$F$4:$F$100=8), 3), "") | D30: =IFERROR(INDEX(_xlfn.FILTER('Contenido Curricular'!$C$4:$C$100, 'Contenido Curricular'!$F$4:$F$100=8), 3), "") | F30: =IFERROR(INDEX(_xlfn.FILTER('Contenido Curricular'!$D$4:$D$100, 'Contenido Curricular'!$F$4:$F$100=8), 3), "")
A31: 4 | B31: =IFERROR(INDEX(_xlfn.FILTER('Contenido Curricular'!$B$4:$B$100, 'Contenido Curricular'!$F$4:$F$100=8), 4), "") | D31: =IFERROR(INDEX(_xlfn.FILTER('Contenido Curricular'!$C$4:$C$100, 'Contenido Curricular'!$F$4:$F$100=8), 4), "") | F31: =IFERROR(INDEX(_xlfn.FILTER('Contenido Curricular'!$D$4:$D$100, 'Contenido Curricular'!$F$4:$F$100=8), 4), "")
A32: 5 | B32: =IFERROR(INDEX(_xlfn.FILTER('Contenido Curricular'!$B$4:$B$100, 'Contenido Curricular'!$F$4:$F$100=8), 5), "") | D32: =IFERROR(INDEX(_xlfn.FILTER('Contenido Curricular'!$C$4:$C$100, 'Contenido Curricular'!$F$4:$F$100=8), 5), "") | F32: =IFERROR(INDEX(_xlfn.FILTER('Contenido Curricular'!$D$4:$D$100, 'Contenido Curricular'!$F$4:$F$100=8), 5), "")
A33: 6 | B33: =IFERROR(INDEX(_xlfn.FILTER('Contenido Curricular'!$B$4:$B$100, 'Contenido Curricular'!$F$4:$F$100=8), 6), "") | D33: =IFERROR(INDEX(_xlfn.FILTER('Contenido Curricular'!$C$4:$C$100, 'Contenido Curricular'!$F$4:$F$100=8), 6), "") | F33: =IFERROR(INDEX(_xlfn.FILTER('Contenido Curricular'!$D$4:$D$100, 'Contenido Curricular'!$F$4:$F$100=8), 6), "")
A34: 7 | B34: =IFERROR(INDEX(_xlfn.FILTER('Contenido Curricular'!$B$4:$B$100, 'Contenido Curricular'!$F$4:$F$100=8), 7), "") | D34: =IFERROR(INDEX(_xlfn.FILTER('Contenido Curricular'!$C$4:$C$100, 'Contenido Curricular'!$F$4:$F$100=8), 7), "") | F34: =IFERROR(INDEX(_xlfn.FILTER('Contenido Curricular'!$D$4:$D$100, 'Contenido Curricular'!$F$4:$F$100=8), 7), "")
A35: 8 | B35: =IFERROR(INDEX(_xlfn.FILTER('Contenido Curricular'!$B$4:$B$100, 'Contenido Curricular'!$F$4:$F$100=8), 8), "") | D35: =IFERROR(INDEX(_xlfn.FILTER('Contenido Curricular'!$C$4:$C$100, 'Contenido Curricular'!$F$4:$F$100=8), 8), "") | F35: =IFERROR(INDEX(_xlfn.FILTER('Contenido Curricular'!$D$4:$D$100, 'Contenido Curricular'!$F$4:$F$100=8), 8), "")
A36: 9 | B36: =IFERROR(INDEX(_xlfn.FILTER('Contenido Curricular'!$B$4:$B$100, 'Contenido Curricular'!$F$4:$F$100=8), 9), "") | D36: =IFERROR(INDEX(_xlfn.FILTER('Contenido Curricular'!$C$4:$C$100, 'Contenido Curricular'!$F$4:$F$100=8), 9), "") | F36: =IFERROR(INDEX(_xlfn.FILTER('Contenido Curricular'!$D$4:$D$100, 'Contenido Curricular'!$F$4:$F$100=8), 9), "")
A37: 10 | B37: =IFERROR(INDEX(_xlfn.FILTER('Contenido Curricular'!$B$4:$B$100, 'Contenido Curricular'!$F$4:$F$100=8), 10), "") | D37: =IFERROR(INDEX(_xlfn.FILTER('Contenido Curricular'!$C$4:$C$100, 'Contenido Curricular'!$F$4:$F$100=8), 10), "") | F37: =IFERROR(INDEX(_xlfn.FILTER('Contenido Curricular'!$D$4:$D$100, 'Contenido Curricular'!$F$4:$F$100=8), 10), "")
A38: 2.2 Recursos Educativos
A39: Tipo de Recurso a utilizar | C39: Tipo | E39: Rango Aproximando | G39: Tiempo Aproximado
A40: Presentacion | C40: Obligatorio | E40: 15-25 minutos | G40: 25
A41: Video | C41: Obligatorio | E41: 3 a 6 minutos | G41: 10
A42: Lectura | C42: Optativo | E42: 3-5 minutos | G42: 5
A43: Ejercicio Demostrativo | C43: Obligatorio | E43: 20-25 minutos | G43: 25
A45: 3. Área de Habilidades (Saber Hacer) | G45: Tiempo | H45: 35
G46: Tiene que estar en un rango de 30 a 50 minutos
A47: Actividad 1 (Obligatoria)
A48: Competencia que predomina en la actividad
A49: Tipo de Actividad | B49: Ejercicio practico
A50: Ponderación | B50: 0
...

Sheet S. 9
B2: Diseño de la Sesión de Laboratorio
B4: Curso | C4: 770 - Introducción a la Programación y Computación 1
B5: Semana | C5: 9
B6: Tiempo | C6: =H10+H21+H45+H70
B7: Ponderación | C7: =B50+B61
B8: Validación de Tiempo | C8: =IF(H51<=0, "❌ ERROR: La Actividad 1 debe tener un tiempo mayor a 0.", IF(H21>60, "❌ ERROR: El 'Área de Conocimiento' no puede exceder los 60 min.", IF((H10+H21+H45)<100, "❌ ERROR: El tiempo total debe ser de al menos 100 min.", "✅ VALIDACIÓN CORRECTA")))
A10: 1. Área Actitudinal (Saber Ser) | G10: Tiempo | H10: 5
G11: Tiene que estar en un rango de 3 a 5 minutos
A12: Nombre del Valor
A13: Tiempo Aproximado
A14: Descripcion
A17: Como se relaciona con los conocimientos de la sesion y se aplicaria
A21: 2. Área Conocimiento (Saber) | G21: Tiempo | H21: 60
G22: No puede exceder los 60 minutos
A23: Competencia a desarrollar
A24: Competencia a desarrollar
A26: 2.1 Contenido
A27: No. | B27: Unidad | D27: Tema | F27: Sub Tema
A28: 1 | B28: =IFERROR(INDEX(_xlfn.FILTER('Contenido Curricular'!$B$4:$B$100, 'Contenido Curricular'!$F$4:$F$100=9), 1), "") | D28: =IFERROR(INDEX(_xlfn.FILTER('Contenido Curricular'!$C$4:$C$100, 'Contenido Curricular'!$F$4:$F$100=9), 1), "") | F28: =IFERROR(INDEX(_xlfn.FILTER('Contenido Curricular'!$D$4:$D$100, 'Contenido Curricular'!$F$4:$F$100=9), 1), "")
A29: 2 | B29: =IFERROR(INDEX(_xlfn.FILTER('Contenido Curricular'!$B$4:$B$100, 'Contenido Curricular'!$F$4:$F$100=9), 2), "") | D29: =IFERROR(INDEX(_xlfn.FILTER('Contenido Curricular'!$C$4:$C$100, 'Contenido Curricular'!$F$4:$F$100=9), 2), "") | F29: =IFERROR(INDEX(_xlfn.FILTER('Contenido Curricular'!$D$4:$D$100, 'Contenido Curricular'!$F$4:$F$100=9), 2), "")
A30: 3 | B30: =IFERROR(INDEX(_xlfn.FILTER('Contenido Curricular'!$B$4:$B$100, 'Contenido Curricular'!$F$4:$F$100=9), 3), "") | D30: =IFERROR(INDEX(_xlfn.FILTER('Contenido Curricular'!$C$4:$C$100, 'Contenido Curricular'!$F$4:$F$100=9), 3), "") | F30: =IFERROR(INDEX(_xlfn.FILTER('Contenido Curricular'!$D$4:$D$100, 'Contenido Curricular'!$F$4:$F$100=9), 3), "")
A31: 4 | B31: =IFERROR(INDEX(_xlfn.FILTER('Contenido Curricular'!$B$4:$B$100, 'Contenido Curricular'!$F$4:$F$100=9), 4), "") | D31: =IFERROR(INDEX(_xlfn.FILTER('Contenido Curricular'!$C$4:$C$100, 'Contenido Curricular'!$F$4:$F$100=9), 4), "") | F31: =IFERROR(INDEX(_xlfn.FILTER('Contenido Curricular'!$D$4:$D$100, 'Contenido Curricular'!$F$4:$F$100=9), 4), "")
A32: 5 | B32: =IFERROR(INDEX(_xlfn.FILTER('Contenido Curricular'!$B$4:$B$100, 'Contenido Curricular'!$F$4:$F$100=9), 5), "") | D32: =IFERROR(INDEX(_xlfn.FILTER('Contenido Curricular'!$C$4:$C$100, 'Contenido Curricular'!$F$4:$F$100=9), 5), "") | F32: =IFERROR(INDEX(_xlfn.FILTER('Contenido Curricular'!$D$4:$D$100, 'Contenido Curricular'!$F$4:$F$100=9), 5), "")
A33: 6 | B33: =IFERROR(INDEX(_xlfn.FILTER('Contenido Curricular'!$B$4:$B$100, 'Contenido Curricular'!$F$4:$F$100=9), 6), "") | D33: =IFERROR(INDEX(_xlfn.FILTER('Contenido Curricular'!$C$4:$C$100, 'Contenido Curricular'!$F$4:$F$100=9), 6), "") | F33: =IFERROR(INDEX(_xlfn.FILTER('Contenido Curricular'!$D$4:$D$100, 'Contenido Curricular'!$F$4:$F$100=9), 6), "")
A34: 7 | B34: =IFERROR(INDEX(_xlfn.FILTER('Contenido Curricular'!$B$4:$B$100, 'Contenido Curricular'!$F$4:$F$100=9), 7), "") | D34: =IFERROR(INDEX(_xlfn.FILTER('Contenido Curricular'!$C$4:$C$100, 'Contenido Curricular'!$F$4:$F$100=9), 7), "") | F34: =IFERROR(INDEX(_xlfn.FILTER('Contenido Curricular'!$D$4:$D$100, 'Contenido Curricular'!$F$4:$F$100=9), 7), "")
A35: 8 | B35: =IFERROR(INDEX(_xlfn.FILTER('Contenido Curricular'!$B$4:$B$100, 'Contenido Curricular'!$F$4:$F$100=9), 8), "") | D35: =IFERROR(INDEX(_xlfn.FILTER('Contenido Curricular'!$C$4:$C$100, 'Contenido Curricular'!$F$4:$F$100=9), 8), "") | F35: =IFERROR(INDEX(_xlfn.FILTER('Contenido Curricular'!$D$4:$D$100, 'Contenido Curricular'!$F$4:$F$100=9), 8), "")
A36: 9 | B36: =IFERROR(INDEX(_xlfn.FILTER('Contenido Curricular'!$B$4:$B$100, 'Contenido Curricular'!$F$4:$F$100=9), 9), "") | D36: =IFERROR(INDEX(_xlfn.FILTER('Contenido Curricular'!$C$4:$C$100, 'Contenido Curricular'!$F$4:$F$100=9), 9), "") | F36: =IFERROR(INDEX(_xlfn.FILTER('Contenido Curricular'!$D$4:$D$100, 'Contenido Curricular'!$F$4:$F$100=9), 9), "")
A37: 10 | B37: =IFERROR(INDEX(_xlfn.FILTER('Contenido Curricular'!$B$4:$B$100, 'Contenido Curricular'!$F$4:$F$100=9), 10), "") | D37: =IFERROR(INDEX(_xlfn.FILTER('Contenido Curricular'!$C$4:$C$100, 'Contenido Curricular'!$F$4:$F$100=9), 10), "") | F37: =IFERROR(INDEX(_xlfn.FILTER('Contenido Curricular'!$D$4:$D$100, 'Contenido Curricular'!$F$4:$F$100=9), 10), "")
A38: 2.2 Recursos Educativos
A39: Tipo de Recurso a utilizar | C39: Tipo | E39: Rango Aproximando | G39: Tiempo Aproximado
A40: Presentacion | C40: Obligatorio | E40: 15-25 minutos | G40: 25
A41: Video | C41: Obligatorio | E41: 3 a 6 minutos | G41: 10
A42: Lectura | C42: Optativo | E42: 3-5 minutos | G42: 5
A43: Ejercicio Demostrativo | C43: Obligatorio | E43: 20-25 minutos | G43: 25
A45: 3. Área de Habilidades (Saber Hacer) | G45: Tiempo | H45: 35
G46: Tiene que estar en un rango de 30 a 50 minutos
A47: Actividad 1 (Obligatoria)
A48: Competencia que predomina en la actividad
A49: Tipo de Actividad | B49: Ejercicio practico
A50: Ponderación | B50: 0
...

Sheet S. 10
B2: Diseño de la Sesión de Laboratorio
B4: Curso | C4: 770 - Introducción a la Programación y Computación 1
B5: Semana | C5: 10
B6: Tiempo | C6: =H10+H21+H45+H70
B7: Ponderación | C7: =B50+B61
B8: Validación de Tiempo | C8: =IF(H51<=0, "❌ ERROR: La Actividad 1 debe tener un tiempo mayor a 0.", IF(H21>60, "❌ ERROR: El 'Área de Conocimiento' no puede exceder los 60 min.", IF((H10+H21+H45)<100, "❌ ERROR: El tiempo total debe ser de al menos 100 min.", "✅ VALIDACIÓN CORRECTA")))
A10: 1. Área Actitudinal (Saber Ser) | G10: Tiempo | H10: 5
G11: Tiene que estar en un rango de 3 a 5 minutos
A12: Nombre del Valor
A13: Tiempo Aproximado
A14: Descripcion
A17: Como se relaciona con los conocimientos de la sesion y se aplicaria
A21: 2. Área Conocimiento (Saber) | G21: Tiempo | H21: 60
G22: No puede exceder los 60 minutos
A23: Competencia a desarrollar
A24: Competencia a desarrollar
A26: 2.1 Contenido
A27: No. | B27: Unidad | D27: Tema | F27: Sub Tema
A28: 1 | B28: =IFERROR(INDEX(_xlfn.FILTER('Contenido Curricular'!$B$4:$B$100, 'Contenido Curricular'!$F$4:$F$100=10), 1), "") | D28: =IFERROR(INDEX(_xlfn.FILTER('Contenido Curricular'!$C$4:$C$100, 'Contenido Curricular'!$F$4:$F$100=10), 1), "") | F28: =IFERROR(INDEX(_xlfn.FILTER('Contenido Curricular'!$D$4:$D$100, 'Contenido Curricular'!$F$4:$F$100=10), 1), "")
A29: 2 | B29: =IFERROR(INDEX(_xlfn.FILTER('Contenido Curricular'!$B$4:$B$100, 'Contenido Curricular'!$F$4:$F$100=10), 2), "") | D29: =IFERROR(INDEX(_xlfn.FILTER('Contenido Curricular'!$C$4:$C$100, 'Contenido Curricular'!$F$4:$F$100=10), 2), "") | F29: =IFERROR(INDEX(_xlfn.FILTER('Contenido Curricular'!$D$4:$D$100, 'Contenido Curricular'!$F$4:$F$100=10), 2), "")
A30: 3 | B30: =IFERROR(INDEX(_xlfn.FILTER('Contenido Curricular'!$B$4:$B$100, 'Contenido Curricular'!$F$4:$F$100=10), 3), "") | D30: =IFERROR(INDEX(_xlfn.FILTER('Contenido Curricular'!$C$4:$C$100, 'Contenido Curricular'!$F$4:$F$100=10), 3), "") | F30: =IFERROR(INDEX(_xlfn.FILTER('Contenido Curricular'!$D$4:$D$100, 'Contenido Curricular'!$F$4:$F$100=10), 3), "")
A31: 4 | B31: =IFERROR(INDEX(_xlfn.FILTER('Contenido Curricular'!$B$4:$B$100, 'Contenido Curricular'!$F$4:$F$100=10), 4), "") | D31: =IFERROR(INDEX(_xlfn.FILTER('Contenido Curricular'!$C$4:$C$100, 'Contenido Curricular'!$F$4:$F$100=10), 4), "") | F31: =IFERROR(INDEX(_xlfn.FILTER('Contenido Curricular'!$D$4:$D$100, 'Contenido Curricular'!$F$4:$F$100=10), 4), "")
A32: 5 | B32: =IFERROR(INDEX(_xlfn.FILTER('Contenido Curricular'!$B$4:$B$100, 'Contenido Curricular'!$F$4:$F$100=10), 5), "") | D32: =IFERROR(INDEX(_xlfn.FILTER('Contenido Curricular'!$C$4:$C$100, 'Contenido Curricular'!$F$4:$F$100=10), 5), "") | F32: =IFERROR(INDEX(_xlfn.FILTER('Contenido Curricular'!$D$4:$D$100, 'Contenido Curricular'!$F$4:$F$100=10), 5), "")
A33: 6 | B33: =IFERROR(INDEX(_xlfn.FILTER('Contenido Curricular'!$B$4:$B$100, 'Contenido Curricular'!$F$4:$F$100=10), 6), "") | D33: =IFERROR(INDEX(_xlfn.FILTER('Contenido Curricular'!$C$4:$C$100, 'Contenido Curricular'!$F$4:$F$100=10), 6), "") | F33: =IFERROR(INDEX(_xlfn.FILTER('Contenido Curricular'!$D$4:$D$100, 'Contenido Curricular'!$F$4:$F$100=10), 6), "")
A34: 7 | B34: =IFERROR(INDEX(_xlfn.FILTER('Contenido Curricular'!$B$4:$B$100, 'Contenido Curricular'!$F$4:$F$100=10), 7), "") | D34: =IFERROR(INDEX(_xlfn.FILTER('Contenido Curricular'!$C$4:$C$100, 'Contenido Curricular'!$F$4:$F$100=10), 7), "") | F34: =IFERROR(INDEX(_xlfn.FILTER('Contenido Curricular'!$D$4:$D$100, 'Contenido Curricular'!$F$4:$F$100=10), 7), "")
A35: 8 | B35: =IFERROR(INDEX(_xlfn.FILTER('Contenido Curricular'!$B$4:$B$100, 'Contenido Curricular'!$F$4:$F$100=10), 8), "") | D35: =IFERROR(INDEX(_xlfn.FILTER('Contenido Curricular'!$C$4:$C$100, 'Contenido Curricular'!$F$4:$F$100=10), 8), "") | F35: =IFERROR(INDEX(_xlfn.FILTER('Contenido Curricular'!$D$4:$D$100, 'Contenido Curricular'!$F$4:$F$100=10), 8), "")
A36: 9 | B36: =IFERROR(INDEX(_xlfn.FILTER('Contenido Curricular'!$B$4:$B$100, 'Contenido Curricular'!$F$4:$F$100=10), 9), "") | D36: =IFERROR(INDEX(_xlfn.FILTER('Contenido Curricular'!$C$4:$C$100, 'Contenido Curricular'!$F$4:$F$100=10), 9), "") | F36: =IFERROR(INDEX(_xlfn.FILTER('Contenido Curricular'!$D$4:$D$100, 'Contenido Curricular'!$F$4:$F$100=10), 9), "")
A37: 10 | B37: =IFERROR(INDEX(_xlfn.FILTER('Contenido Curricular'!$B$4:$B$100, 'Contenido Curricular'!$F$4:$F$100=10), 10), "") | D37: =IFERROR(INDEX(_xlfn.FILTER('Contenido Curricular'!$C$4:$C$100, 'Contenido Curricular'!$F$4:$F$100=10), 10), "") | F37: =IFERROR(INDEX(_xlfn.FILTER('Contenido Curricular'!$D$4:$D$100, 'Contenido Curricular'!$F$4:$F$100=10), 10), "")
A38: 2.2 Recursos Educativos
A39: Tipo de Recurso a utilizar | C39: Tipo | E39: Rango Aproximando | G39: Tiempo Aproximado
A40: Presentacion | C40: Obligatorio | E40: 15-25 minutos | G40: 25
A41: Video | C41: Obligatorio | E41: 3 a 6 minutos | G41: 10
A42: Lectura | C42: Optativo | E42: 3-5 minutos | G42: 5
A43: Ejercicio Demostrativo | C43: Obligatorio | E43: 20-25 minutos | G43: 25
A45: 3. Área de Habilidades (Saber Hacer) | G45: Tiempo | H45: 35
G46: Tiene que estar en un rango de 30 a 50 minutos
A47: Actividad 1 (Obligatoria)
A48: Competencia que predomina en la actividad
A49: Tipo de Actividad | B49: Ejercicio practico
A50: Ponderación | B50: 0
...

Sheet S. 11
B2: Diseño de la Sesión de Laboratorio
B4: Curso | C4: 770 - Introducción a la Programación y Computación 1
B5: Semana | C5: 11
B6: Tiempo | C6: =H10+H21+H45+H70
B7: Ponderación | C7: =B50+B61
B8: Validación de Tiempo | C8: =IF(H51<=0, "❌ ERROR: La Actividad 1 debe tener un tiempo mayor a 0.", IF(H21>60, "❌ ERROR: El 'Área de Conocimiento' no puede exceder los 60 min.", IF((H10+H21+H45)<100, "❌ ERROR: El tiempo total debe ser de al menos 100 min.", "✅ VALIDACIÓN CORRECTA")))
A10: 1. Área Actitudinal (Saber Ser) | G10: Tiempo | H10: 5
G11: Tiene que estar en un rango de 3 a 5 minutos
A12: Nombre del Valor
A13: Tiempo Aproximado
A14: Descripcion
A17: Como se relaciona con los conocimientos de la sesion y se aplicaria
A21: 2. Área Conocimiento (Saber) | G21: Tiempo | H21: 60
G22: No puede exceder los 60 minutos
A23: Competencia a desarrollar
A24: Competencia a desarrollar
A26: 2.1 Contenido
A27: No. | B27: Unidad | D27: Tema | F27: Sub Tema
A28: 1 | B28: =IFERROR(INDEX(_xlfn.FILTER('Contenido Curricular'!$B$4:$B$100, 'Contenido Curricular'!$F$4:$F$100=11), 1), "") | D28: =IFERROR(INDEX(_xlfn.FILTER('Contenido Curricular'!$C$4:$C$100, 'Contenido Curricular'!$F$4:$F$100=11), 1), "") | F28: =IFERROR(INDEX(_xlfn.FILTER('Contenido Curricular'!$D$4:$D$100, 'Contenido Curricular'!$F$4:$F$100=11), 1), "")
A29: 2 | B29: =IFERROR(INDEX(_xlfn.FILTER('Contenido Curricular'!$B$4:$B$100, 'Contenido Curricular'!$F$4:$F$100=11), 2), "") | D29: =IFERROR(INDEX(_xlfn.FILTER('Contenido Curricular'!$C$4:$C$100, 'Contenido Curricular'!$F$4:$F$100=11), 2), "") | F29: =IFERROR(INDEX(_xlfn.FILTER('Contenido Curricular'!$D$4:$D$100, 'Contenido Curricular'!$F$4:$F$100=11), 2), "")
A30: 3 | B30: =IFERROR(INDEX(_xlfn.FILTER('Contenido Curricular'!$B$4:$B$100, 'Contenido Curricular'!$F$4:$F$100=11), 3), "") | D30: =IFERROR(INDEX(_xlfn.FILTER('Contenido Curricular'!$C$4:$C$100, 'Contenido Curricular'!$F$4:$F$100=11), 3), "") | F30: =IFERROR(INDEX(_xlfn.FILTER('Contenido Curricular'!$D$4:$D$100, 'Contenido Curricular'!$F$4:$F$100=11), 3), "")
A31: 4 | B31: =IFERROR(INDEX(_xlfn.FILTER('Contenido Curricular'!$B$4:$B$100, 'Contenido Curricular'!$F$4:$F$100=11), 4), "") | D31: =IFERROR(INDEX(_xlfn.FILTER('Contenido Curricular'!$C$4:$C$100, 'Contenido Curricular'!$F$4:$F$100=11), 4), "") | F31: =IFERROR(INDEX(_xlfn.FILTER('Contenido Curricular'!$D$4:$D$100, 'Contenido Curricular'!$F$4:$F$100=11), 4), "")
A32: 5 | B32: =IFERROR(INDEX(_xlfn.FILTER('Contenido Curricular'!$B$4:$B$100, 'Contenido Curricular'!$F$4:$F$100=11), 5), "") | D32: =IFERROR(INDEX(_xlfn.FILTER('Contenido Curricular'!$C$4:$C$100, 'Contenido Curricular'!$F$4:$F$100=11), 5), "") | F32: =IFERROR(INDEX(_xlfn.FILTER('Contenido Curricular'!$D$4:$D$100, 'Contenido Curricular'!$F$4:$F$100=11), 5), "")
A33: 6 | B33: =IFERROR(INDEX(_xlfn.FILTER('Contenido Curricular'!$B$4:$B$100, 'Contenido Curricular'!$F$4:$F$100=11), 6), "") | D33: =IFERROR(INDEX(_xlfn.FILTER('Contenido Curricular'!$C$4:$C$100, 'Contenido Curricular'!$F$4:$F$100=11), 6), "") | F33: =IFERROR(INDEX(_xlfn.FILTER('Contenido Curricular'!$D$4:$D$100, 'Contenido Curricular'!$F$4:$F$100=11), 6), "")
A34: 7 | B34: =IFERROR(INDEX(_xlfn.FILTER('Contenido Curricular'!$B$4:$B$100, 'Contenido Curricular'!$F$4:$F$100=11), 7), "") | D34: =IFERROR(INDEX(_xlfn.FILTER('Contenido Curricular'!$C$4:$C$100, 'Contenido Curricular'!$F$4:$F$100=11), 7), "") | F34: =IFERROR(INDEX(_xlfn.FILTER('Contenido Curricular'!$D$4:$D$100, 'Contenido Curricular'!$F$4:$F$100=11), 7), "")
A35: 8 | B35: =IFERROR(INDEX(_xlfn.FILTER('Contenido Curricular'!$B$4:$B$100, 'Contenido Curricular'!$F$4:$F$100=11), 8), "") | D35: =IFERROR(INDEX(_xlfn.FILTER('Contenido Curricular'!$C$4:$C$100, 'Contenido Curricular'!$F$4:$F$100=11), 8), "") | F35: =IFERROR(INDEX(_xlfn.FILTER('Contenido Curricular'!$D$4:$D$100, 'Contenido Curricular'!$F$4:$F$100=11), 8), "")
A36: 9 | B36: =IFERROR(INDEX(_xlfn.FILTER('Contenido Curricular'!$B$4:$B$100, 'Contenido Curricular'!$F$4:$F$100=11), 9), "") | D36: =IFERROR(INDEX(_xlfn.FILTER('Contenido Curricular'!$C$4:$C$100, 'Contenido Curricular'!$F$4:$F$100=11), 9), "") | F36: =IFERROR(INDEX(_xlfn.FILTER('Contenido Curricular'!$D$4:$D$100, 'Contenido Curricular'!$F$4:$F$100=11), 9), "")
A37: 10 | B37: =IFERROR(INDEX(_xlfn.FILTER('Contenido Curricular'!$B$4:$B$100, 'Contenido Curricular'!$F$4:$F$100=11), 10), "") | D37: =IFERROR(INDEX(_xlfn.FILTER('Contenido Curricular'!$C$4:$C$100, 'Contenido Curricular'!$F$4:$F$100=11), 10), "") | F37: =IFERROR(INDEX(_xlfn.FILTER('Contenido Curricular'!$D$4:$D$100, 'Contenido Curricular'!$F$4:$F$100=11), 10), "")
A38: 2.2 Recursos Educativos
A39: Tipo de Recurso a utilizar | C39: Tipo | E39: Rango Aproximando | G39: Tiempo Aproximado
A40: Presentacion | C40: Obligatorio | E40: 15-25 minutos | G40: 25
A41: Video | C41: Obligatorio | E41: 3 a 6 minutos | G41: 10
A42: Lectura | C42: Optativo | E42: 3-5 minutos | G42: 5
A43: Ejercicio Demostrativo | C43: Obligatorio | E43: 20-25 minutos | G43: 25
A45: 3. Área de Habilidades (Saber Hacer) | G45: Tiempo | H45: 35
G46: Tiene que estar en un rango de 30 a 50 minutos
A47: Actividad 1 (Obligatoria)
A48: Competencia que predomina en la actividad
A49: Tipo de Actividad | B49: Ejercicio practico
A50: Ponderación | B50: 0
...
